Workbook

Sheet 요약
A1: 개별주식 일일 매매규칙 v1 - 요약
A2: 대상: 코스피200+코스닥150 현 구성종목 344개, 2016-10-11 ~ 2026-10-08 일봉 (수정주가). 판정 시작 2017-10. 현 구성종목이라 생존편향이 들어 있음 - 수치는 상한.
A4: 항목 | B4: 값 | C4: 설명
A5: 거래 건수 | B5: =COUNTA(거래!A5:A593) -> 589
A6: 승률 | B6: =COUNTIF(거래!K5:K593,">0")/COUNTA(거래!A5:A593) -> 0.32258065
A7: 건당 평균 수익률 | B7: =AVERAGE(거래!K5:K593) -> 0.052228675 | C7: 비용 포함
A8: 건당 중앙값 | B8: =MEDIAN(거래!K5:K593) -> -0.03516042
A9: 최고 1건 | B9: =MAX(거래!K5:K593) -> 6.3037564
A10: 최악 1건 | B10: =MIN(거래!K5:K593) -> -0.34993717
A11: 평균 보유일 | B11: =AVERAGE(거래!L5:L593) -> 21.179966
A12: 손절 건수 | B12: =COUNTIF(거래!M5:M593,"손절") -> 208
A13: CAGR (복리) | B13: 0.27002204 | C13: 일간 평가, 2017-10-02 ~ 2026-10-08
A14: 최대 낙폭 | B14: -0.43982522 | C14: 2026-05-29 ~ 2026-08-03
A15: Sharpe | B15: 0.88544597
A16: 최종 배수 | B16: 8.5834491
A17: IS 2017-10~2021 / OOS 2022~2026-10 | B17: 22.9% / 30.8% | C17: CAGR (MDD -35.4% / -44.0%)
A18: 2025~26 제외 | B18: 27.2% / -35.4% / 0.97 | C18: CAGR / MDD / Sharpe
A19: 비교: 같은 진입, 패턴별 청산 | B19: 17.8% / -40.7% / 0.73 | C19: 62일선 청산 대신 패턴 고유 청산
A20: 비교: 후보 순위를 무작위로 | B20: 12.6% / -36.8% / 0.61 | C20: 6개월 수익률 순위의 값
A21: 비교: 변형 B (월말 6개월 모멘텀 상위10, 패턴 없음) | B21: 31.9% / -31.2% / 1.09 | C21: 변형_월말모멘텀 시트
A22: 비교: 코스피200 ETF 11패턴 (같은 창) | B22: 21.2% / -31.8% / 0.96
A23: 비교: 유니버스 동일가중 보유 | B23: 17.6% / -45.3% / 0.81 | C23: 같은 생존편향
A24: 비교: 코스피200 지수 | B24: 14.0% / -41.2% / 0.63
A26: 연도별 수익률 (복리)
A27: 2017 | B27: 0
A28: 2018 | B28: -0.052558061
A29: 2019 | B29: 0.077752066
A30: 2020 | B30: 0.93726692
A31: 2021 | B31: 0.20691443
A32: 2022 | B32: -0.031776222
A33: 2023 | B33: 1.2190513
A34: 2024 | B34: 0.10833674
A35: 2025 | B35: 0.62805522
A36: 2026 | B36: -0.072656847
A39: 패턴(카드)별 기여 (거래 시트에서 집계)
A40: 카드 | B40: 건수 | C40: 승률 | D40: 건당 평균 | E40: 합산
A41: A1 | B41: =COUNTIF(거래!C5:C593,A41) -> 47 | C41: =IFERROR(COUNTIFS(거래!C5:C593,A41,거래!K5:K593,">0")/B41,0) -> 0.44680851 | D41: =IFERROR(AVERAGEIF(거래!C5:C593,A41,거래!K5:K593),0) -> 0.01684571 | E41: =SUMIF(거래!C5:C593,A41,거래!K5:K593) -> 0.79174837
A42: A2 | B42: =COUNTIF(거래!C5:C593,A42) -> 64 | C42: =IFERROR(COUNTIFS(거래!C5:C593,A42,거래!K5:K593,">0")/B42,0) -> 0.375 | D42: =IFERROR(AVERAGEIF(거래!C5:C593,A42,거래!K5:K593),0) -> 0.09109506 | E42: =SUMIF(거래!C5:C593,A42,거래!K5:K593) -> 5.8300839
A43: A3 | B43: =COUNTIF(거래!C5:C593,A43) -> 46 | C43: =IFERROR(COUNTIFS(거래!C5:C593,A43,거래!K5:K593,">0")/B43,0) -> 0.34782609 | D43: =IFERROR(AVERAGEIF(거래!C5:C593,A43,거래!K5:K593),0) -> 0.076900278 | E43: =SUMIF(거래!C5:C593,A43,거래!K5:K593) -> 3.5374128
A44: A4 | B44: =COUNTIF(거래!C5:C593,A44) -> 37 | C44: =IFERROR(COUNTIFS(거래!C5:C593,A44,거래!K5:K593,">0")/B44,0) -> 0.32432432 | D44: =IFERROR(AVERAGEIF(거래!C5:C593,A44,거래!K5:K593),0) -> 0.00063252598 | E44: =SUMIF(거래!C5:C593,A44,거래!K5:K593) -> 0.023403461
...

Sheet 거래
A1: 개별주식 일일 규칙 v1 거래 목록 (2017-10 ~ 2026-10, 백테스트, 비용 반영: 매수 0.10%, 매도 0.25%)
A2: 진입: 15개 패턴 중 하나 통과 + 종가>248일선 + 거래대금 30억 + 코스피200 62일선 상승 → 신호 다음날 종가 매수 (10% x 10). 청산: 종가 < 62일선 → 다음날 시가. 손절: 신호일 종가 - 2 ATR (장중). 후보 순위: 6개월 수익률.
A4: 종목코드 | B4: 종목명 | C4: 카드 | D4: 진입 패턴 | E4: 신호일 | F4: 매수일 (종가) | G4: 매수가 | H4: 매도일 | I4: 매도가 | J4: 손절가 | K4: 수익률 (비용 포함) | L4: 보유일 | M4: 사유
A5: 005290 | B5: 동진쎄미켐 | C5: A1 | D5: MACD 골든크로스 + 62일선 상승 | E5: 43097 | F5: 43102 | G5: 20700 | H5: 43103 | I5: 21000 | J5: 20050 | K5: =I5/G5*(1-0.0025)/(1+0.001)-1 -> 0.010945576 | L5: 1 | M5: 추세이탈
A6: 064760 | B6: 티씨케이 | C6: B1 | D6: 52주 신고가 + 정배열 | E6: 43097 | F6: 43102 | G6: 76300 | H6: 43108 | I6: 69740 | J6: 69740 | K6: =I6/G6*(1-0.0025)/(1+0.001)-1 -> -0.089172296 | L6: 4 | M6: 손절
A7: 066970 | B7: 엘앤에프 | C7: A1 | D7: MACD 골든크로스 + 62일선 상승 | E7: 43097 | F7: 43102 | G7: 39960 | H7: 43110 | I7: 36853 | J7: 35894.2 | K7: =I7/G7*(1-0.0025)/(1+0.001)-1 -> -0.080977393 | L7: 6 | M7: 추세이탈
A8: 036620 | B8: 감성코퍼레이션 | C8: B3 | D8: 55일 고가 돌파 | E8: 43108 | F8: 43109 | G8: 2360 | H8: 43111 | I8: 2081.7 | J8: 2081.7 | K8: =I8/G8*(1-0.0025)/(1+0.001)-1 -> -0.12100791 | L8: 2 | M8: 손절
A9: 128940 | B9: 한미약품 | C9: A1 | D9: MACD 골든크로스 + 62일선 상승 | E9: 43097 | F9: 43102 | G9: 529369 | H9: 43136 | I9: 498962 | J9: 489095.9 | K9: =I9/G9*(1-0.0025)/(1+0.001)-1 -> -0.060735748 | L9: 24 | M9: 추세이탈
A10: 196170 | B10: 알테오젠 | C10: C | D10: 감천 격자 F0.309 상향돌파 + 62일선 상승 | E10: 43097 | F10: 43102 | G10: 4985 | H10: 43137 | I10: 4151 | J10: 3949.9 | K10: =I10/G10*(1-0.0025)/(1+0.001)-1 -> -0.17021344 | L10: 25 | M10: 추세이탈
A11: 041140 | B11: 넥슨게임즈 | C11: C | D11: 감천 격자 F0.5 상향돌파 + 62일선 상승 | E11: 43133 | F11: 43136 | G11: 13100 | H11: 43137 | I11: 12200 | J11: 12605 | K11: =I11/G11*(1-0.0025)/(1+0.001)-1 -> -0.071958576 | L11: 1 | M11: 추세이탈
A12: 008770 | B12: 호텔신라 | C12: B4 | D12: 20일 박스(폭 20% 이내) 상단 돌파 + 거래량 1.5배 | E12: 43109 | F12: 43110 | G12: 93300 | H12: 43138 | I12: 82760 | J12: 82760 | K12: =I12/G12*(1-0.0025)/(1+0.001)-1 -> -0.11607042 | L12: 20 | M12: 손절
A13: 041190 | B13: 우리기술투자 | C13: C | D13: 감천 격자 F0.309 상향돌파 + 62일선 상승 | E13: 43102 | F13: 43103 | G13: 4905 | H13: 43167 | I13: 4900 | J13: 3210 | K13: =I13/G13*(1-0.0025)/(1+0.001)-1 -> -0.0045123073 | L13: 43 | M13: 추세이탈
A14: 007390 | B14: 네이처셀 | C14: C | D14: 감천 격자 F0.5 상향돌파 + 62일선 상승 | E14: 43097 | F14: 43102 | G14: 22916 | H14: 43181 | I14: 29981 | K14: =I14/G14*(1-0.0025)/(1+0.001)-1 -> 0.3037254 | L14: 54 | M14: 추세이탈
A15: 085660 | B15: 차바이오텍 | C15: A1 | D15: MACD 골든크로스 + 62일선 상승 | E15: 43097 | F15: 43102 | G15: 27002 | H15: 43182 | I15: 21878 | J15: 17534.1 | K15: =I15/G15*(1-0.0025)/(1+0.001)-1 -> -0.19259672 | L15: 55 | M15: 추세이탈
A16: 068760 | B16: 셀트리온제약 | C16: A3 | D16: 5일선/21일선 골든크로스 + 5일 수익 양수 + 62일선 상승 | E16: 43097 | F16: 43102 | G16: 48256 | H16: 43185 | I16: 62747 | J16: 40628 | K16: =I16/G16*(1-0.0025)/(1+0.001)-1 -> 0.29574778 | L16: 56 | M16: 추세이탈
A17: 009420 | B17: 한올바이오파마 | C17: B1 | D17: 52주 신고가 + 정배열 | E17: 43097 | F17: 43102 | G17: 25250 | H17: 43185 | I17: 32250 | J17: 21255 | K17: =I17/G17*(1-0.0025)/(1+0.001)-1 -> 0.27276189 | L17: 56 | M17: 추세이탈
A18: 068270 | B18: 셀트리온 | C18: A3 | D18: 5일선/21일선 골든크로스 + 5일 수익 양수 + 62일선 상승 | E18: 43097 | F18: 43102 | G18: 172576 | H18: 43186 | I18: 234532 | J18: 155272.8 | K18: =I18/G18*(1-0.0025)/(1+0.001)-1 -> 0.35425527 | L18: 57 | M18: 추세이탈
A19: 003670 | B19: 포스코퓨처엠 | C19: B1 | D19: 52주 신고가 + 정배열 | E19: 43111 | F19: 43112 | G19: 42714 | H19: 43194 | I19: 41986 | J19: 35741.8 | K19: =I19/G19*(1-0.0025)/(1+0.001)-1 -> -0.020480503 | L19: 55 | M19: 추세이탈
A20: 222080 | B20: 씨아이에스 | C20: C | D20: 감천 격자 F0.382 상향돌파 + 62일선 상승 | E20: 43255 | F20: 43256 | G20: 2520 | H20: 43258 | I20: 2545 | J20: 2220 | K20: =I20/G20*(1-0.0025)/(1+0.001)-1 -> 0.0063894439 | L20: 1 | M20: 추세이탈
A21: 086520 | B21: 에코프로 | C21: A4 | D21: 62일선 상향돌파 + RSI 40~60 + 62일선 상승 | E21: 43255 | F21: 43256 | G21: 4895 | H21: 43258 | I21: 5065 | J21: 4488.8 | K21: =I21/G21*(1-0.0025)/(1+0.001)-1 -> 0.031111381 | L21: 1 | M21: 추세이탈
A22: 180640 | B22: 한진칼 | C22: A3 | D22: 5일선/21일선 골든크로스 + 5일 수익 양수 + 62일선 상승 | E22: 43255 | F22: 43256 | G22: 22400 | H22: 43259 | I22: 21250 | J22: 20770 | K22: =I22/G22*(1-0.0025)/(1+0.001)-1 -> -0.054656281 | L22: 2 | M22: 추세이탈
A23: 000250 | B23: 삼천당제약 | C23: C | D23: 감천 격자 F0.309 상향돌파 + 62일선 상승 | E23: 43258 | F23: 43259 | G23: 43950 | H23: 43262 | I23: 43950 | J23: 39780 | K23: =I23/G23*(1-0.0025)/(1+0.001)-1 -> -0.0034965035 | L23: 1 | M23: 추세이탈
A24: 047050 | B24: 포스코인터내셔널 | C24: A2 | D24: RSI 50 상향돌파 + 히스토 음수 + 62일선 상승 | E24: 43256 | F24: 43258 | G24: 23650 | H24: 43269 | I24: 22900 | J24: 21455 | K24: =I24/G24*(1-0.0025)/(1+0.001)-1 -> -0.035098094 | L24: 6 | M24: 추세이탈
A25: 036830 | B25: 솔브레인홀딩스 | C25: B3 | D25: 55일 고가 돌파 | E25: 43256 | F25: 43258 | G25: 35255 | H25: 43269 | I25: 32704.4 | J25: 32704.4 | K25: =I25/G25*(1-0.0025)/(1+0.001)-1 -> -0.075590726 | L25: 6 | M25: 손절
A26: 018290 | B26: 브이티 | C26: A1 | D26: MACD 골든크로스 + 62일선 상승 | E26: 43259 | F26: 43262 | G26: 8060 | H26: 43269 | I26: 7459 | J26: 7459 | K26: =I26/G26*(1-0.0025)/(1+0.001)-1 -> -0.077801541 | L26: 4 | M26: 손절
... A30: 096770 | B30: SK이노베이션 | C30: A3 | D30: 5일선/21일선 골든크로스 + 5일 수익 양수 + 62일선 상승 | E30: 43255 | F30: 43256 | G30: 202694 | H30: 43271 | I30: 200234 | J30: 195463 | K30: =I30/G30*(1-0.0025)/(1+0.001)-1 -> -0.015590589 | L30: 9 | M30: 추세이탈
A31: 032820 | B31: 우리기술 | C31: C | D31: 감천 격자 F0.5 상향돌파 + 62일선 상승 | E31: 43255 | F31: 43256 | G31: 2340 | H31: 43276 | I31: 1820 | K31: =I31/G31*(1-0.0025)/(1+0.001)-1 -> -0.22494172 | L31: 12 | M31: 추세이탈
A32: 073240 | B32: 금호타이어 | C32: D | D32: 쿨라매기: 60일 +20% 선행 + 15일 박스 돌파 + 거래량 1.3배 | E32: 43266 | F32: 43269 | G32: 6430 | H32: 43280 | I32: 6260 | J32: 6260 | K32: =I32/G32*(1-0.0025)/(1+0.001)-1 -> -0.02984263 | L32: 9 | M32: 손절
A33: 066970 | B33: 엘앤에프 | C33: B1 | D33: 52주 신고가 + 정배열 | E33: 43255 | F33: 43256 | G33: 48582 | H33: 43287 | I33: 43839.9 | J33: 43839.9 | K33: =I33/G33*(1-0.0025)/(1+0.001)-1 -> -0.10076544 | L33: 21 | M33: 손절
A34: 006400 | B34: 삼성SDI | C34: B4 | D34: 20일 박스(폭 20% 이내) 상단 돌파 + 거래량 1.5배 | E34: 43255 | F34: 43256 | G34: 210492 | H34: 43325 | I34: 208533 | J34: 199918 | K34: =I34/G34*(1-0.0025)/(1+0.001)-1 -> -0.012770729 | L34: 47 | M34: 추세이탈
A35: 042660 | B35: 한화오션 | C35: C | D35: 감천 격자 F0.309 상향돌파 + 62일선 상승 | E35: 43503 | F35: 43504 | G35: 29673 | H35: 43507 | I35: 29806 | J35: 27816.1 | K35: =I35/G35*(1-0.0025)/(1+0.001)-1 -> 0.00097001371 | L35: 1 | M35: 추세이탈
A36: 003670 | B36: 포스코퓨처엠 | C36: B4 | D36: 20일 박스(폭 20% 이내) 상단 돌파 + 거래량 1.5배 | E36: 43503 | F36: 43504 | G36: 58591 | H36: 43507 | I36: 58954 | J36: 53914.3 | K36: =I36/G36*(1-0.0025)/(1+0.001)-1 -> 0.0026773247 | L36: 1 | M36: 추세이탈
A37: 010130 | B37: 고려아연 | C37: C | D37: 감천 격자 F0.5 상향돌파 + 62일선 상승 | E37: 43503 | F37: 43504 | G37: 443000 | H37: 43508 | I37: 431000 | J37: 426250 | K37: =I37/G37*(1-0.0025)/(1+0.001)-1 -> -0.030489826 | L37: 2 | M37: 추세이탈
A38: 007660 | B38: 이수페타시스 | C38: C | D38: 감천 격자 F0.5 상향돌파 + 62일선 상승 | E38: 43503 | F38: 43504 | G38: 5519 | H38: 43509 | I38: 5430 | J38: 4734.9 | K38: =I38/G38*(1-0.0025)/(1+0.001)-1 -> -0.019566228 | L38: 3 | M38: 추세이탈
A39: 082740 | B39: 한화엔진 | C39: C | D39: 감천 격자 F0.309 상향돌파 + 62일선 상승 | E39: 43504 | F39: 43507 | G39: 4229 | H39: 43510 | I39: 3953 | J39: 3820.3 | K39: =I39/G39*(1-0.0025)/(1+0.001)-1 -> -0.068531965 | L39: 3 | M39: 추세이탈
A40: 085660 | B40: 차바이오텍 | C40: B4 | D40: 20일 박스(폭 20% 이내) 상단 돌파 + 거래량 1.5배 | E40: 43507 | F40: 43508 | G40: 20678 | H40: 43510 | I40: 19317 | J40: 19317 | K40: =I40/G40*(1-0.0025)/(1+0.001)-1 -> -0.069085113 | L40: 2 | M40: 손절
A41: 007660 | B41: 이수페타시스 | C41: A4 | D41: 62일선 상향돌파 + RSI 40~60 + 62일선 상승 | E41: 43509 | F41: 43510 | G41: 5476 | H41: 43514 | I41: 5302 | J41: 5022.1 | K41: =I41/G41*(1-0.0025)/(1+0.001)-1 -> -0.03516042 | L41: 2 | M41: 추세이탈
A42: 081660 | B42: 미스토홀딩스 | C42: A1 | D42: MACD 골든크로스 + 62일선 상승 | E42: 43510 | F42: 43511 | G42: 47500 | H42: 43514 | I42: 48700 | J42: 44995 | K42: =I42/G42*(1-0.0025)/(1+0.001)-1 -> 0.021678322 | L42: 1 | M42: 추세이탈
A43: 122870 | B43: 와이지엔터테인먼트 | C43: A4 | D43: 62일선 상향돌파 + RSI 40~60 + 62일선 상승 | E43: 43503 | F43: 43504 | G43: 46050 | H43: 43515 | I43: 43300 | J43: 41835 | K43: =I43/G43*(1-0.0025)/(1+0.001)-1 -> -0.063005399 | L43: 7 | M43: 추세이탈
... A593: 051900 | B593: LG생활건강 | C593: B3 | D593: 55일 고가 돌파 | E593: 46233 | F593: 46234 | G593: 287000 | H593: 46295 | I593: 281000 | J593: 265600 | K593: =I593/G593*(1-0.0025)/(1+0.001)-1 -> -0.024329329 | L593: 40 | M593: 추세이탈

Sheet 오늘후보
A1: 2026-10-08 종가 기준 진입 패턴 통과 종목 코스피200 국면: 하락 (신규 매수 없음)
A3: 순위 | B3: 종목코드 | C3: 종목명 | D3: 카드 | E3: 패턴 | F3: 종가 | G3: 손절가 (2ATR) | H3: 손절폭 | I3: 6개월 수익률 | J3: 62일선 | K3: 20일 평균 거래대금(억)
A4: 1 | B4: 031980 | C4: 피에스케이홀딩스 | D4: B1,B2,B3 | E4: 52주 신고가 + 정배열; 20일 고가 돌파; 55일 고가 돌파 | F4: 209500 | G4: 179640 | H4: -0.14252983 | I4: 0.97455231 | J4: 134583.87 | K4: 321.49317
A5: 2 | B5: 131970 | C5: 두산테스나 | D5: B2,B3 | E5: 20일 고가 돌파 + 거래량 1.5배; 20일 고가 돌파; 55일 고가 돌파 | F5: 123300 | G5: 106295 | H5: -0.13791565 | I5: 0.39795918 | J5: 83088.71 | K5: 403.20918
A6: 3 | B6: 098460 | C6: 고영 | D6: B2,B3 | E6: 20일 고가 돌파 + 거래량 1.5배; 20일 고가 돌파; 55일 고가 돌파 | F6: 37350 | G6: 33735 | H6: -0.096787149 | I6: 0.36563071 | J6: 28752.419 | K6: 478.71009
A7: 4 | B7: 006400 | C7: 삼성SDI | D7: A1,A3 | E7: MACD 골든크로스 + 62일선 상승; 5일선/21일선 골든크로스 + 5일 수익 양수 + 62일선 상승 | F7: 567000 | G7: 520400 | H7: -0.082186949 | I7: 0.17879418 | J7: 490217.74 | K7: 1979.272
A8: 5 | B8: 373220 | C8: LG에너지솔루션 | D8: B2,B3,B4,D | E8: 20일 고가 돌파 + 거래량 1.5배; 20일 고가 돌파; 55일 고가 돌파; 20일 박스(폭 20% 이내) 상단 돌파 + 거래량 1.5배; 쿨라매기: 60일 +20% 선행 + 15일 박스 돌파 + 거래량 1.3배 | F8: 403000 | G8: 372000 | H8: -0.076923077 | I8: -0.02184466 | J8: 349806.45 | K8: 1187.9392
A9: 6 | B9: 036830 | C9: 솔브레인홀딩스 | D9: B2,B3 | E9: 20일 고가 돌파 + 거래량 1.5배; 20일 고가 돌파; 55일 고가 돌파 | F9: 50200 | G9: 45435 | H9: -0.094920319 | I9: -0.07037037 | J9: 38631.452 | K9: 32.109524
A10: 7 | B10: 417200 | C10: LS머트리얼즈 | D10: B2,B3 | E10: 20일 고가 돌파 + 거래량 1.5배; 20일 고가 돌파; 55일 고가 돌파 | F10: 16430 | G10: 14326 | H10: -0.12805843 | I10: -0.17767768 | J10: 12059.032 | K10: 218.93009

Sheet 변형_월말모멘텀
A1: 변형 B: 월말 6개월 모멘텀 상위 10 보유 (패턴 없음), 62일선 이탈 매도, 코스피200 국면 - 거래 352건
A3: 종목코드 | B3: 종목명 | C3: 매수일 | D3: 매수가 | E3: 매도일 | F3: 매도가 | G3: 수익률 | H3: 보유일 | I3: 사유
A4: 005420 | B4: 코스모화학 | C4: 43039 | D4: 9830 | E4: 43041 | F4: 10392 | G4: 0.053474464 | H4: 2 | I4: 62일선 이탈
A5: 086520 | B5: 에코프로 | C5: 43039 | D5: 3612 | E5: 43041 | F5: 3680 | G5: 0.015262791 | H5: 2 | I5: 62일선 이탈
A6: 066970 | B6: 엘앤에프 | C6: 43039 | D6: 29993 | E6: 43041 | F6: 32031 | G6: 0.064214036 | H6: 2 | I6: 62일선 이탈
A7: 005290 | B7: 동진쎄미켐 | C7: 43039 | D7: 20600 | E7: 43069 | F7: 22000 | G7: 0.064225971 | H7: 22 | I7: 월말 순위 밖
A8: 207940 | B8: 삼성바이오로직스 | C8: 43039 | D8: 554234 | E8: 43069 | F8: 494337 | G8: -0.1111912 | H8: 22 | I8: 월말 순위 밖
A9: 041190 | B9: 우리기술투자 | C9: 43039 | D9: 1770 | E9: 43081 | F9: 1950 | G9: 0.097841737 | H9: 30 | I9: 62일선 이탈
A10: 066970 | B10: 엘앤에프 | C10: 43069 | D10: 39636 | E10: 43088 | F10: 36435 | G10: -0.083974957 | H10: 13 | I10: 62일선 이탈
A11: 068270 | B11: 셀트리온 | C11: 43039 | D11: 129662 | E11: 43097 | F11: 168908 | G11: 0.29812315 | H11: 41 | I11: 월말 순위 밖
A12: 232140 | B12: 와이씨 | C12: 43097 | D12: 7290 | E12: 43124 | F12: 5700 | G12: -0.22084167 | H12: 17 | I12: 62일선 이탈
A13: 003670 | B13: 포스코퓨처엠 | C13: 43039 | D13: 25565 | E13: 43131 | F13: 44944 | G13: 0.75187985 | H13: 63 | I13: 월말 순위 밖
A14: 086520 | B14: 에코프로 | C14: 43069 | D14: 4698 | E14: 43131 | F14: 5098 | G14: 0.081347328 | H14: 41 | I14: 월말 순위 밖
A15: 078600 | B15: 대주전자재료 | C15: 43069 | D15: 13650 | E15: 43131 | F15: 16800 | G15: 0.22646462 | H15: 41 | I15: 월말 순위 밖
... A355: 009150 | B355: 삼성전기 | C355: 46234 | D355: 1142000 | E355: 46238 | F355: 1278000 | G355: 0.1151753 | H355: 2 | I355: 62일선 이탈

Sheet 패턴검증
A1: 패턴별 교차검증 (344종목, 건별, 비용 0.35% 포함, 각 패턴 고유 청산). IS = 2017-10~2021 / OOS = 2022~2026-10. 초과 = 같은 종목·같은 청산의 무작위 진입 대비. p = IS 순환이동 귀무검정. "+K62상승" = 코스피200 62일선 상승 때만
A3: 패턴 | B3: IS 건수 | C3: IS 승률 | D3: IS 건당 | E3: 귀무 평균 | F3: 초과 | G3: p | H3: OOS 건수 | I3: OOS 승률 | J3: OOS 건당 | K3: OOS t | L3: 손절 비중
A4: C1 CIS 52주신고가+정배열 | B4: 1193 | C4: 0.34953898 | D4: 0.025898165 | E4: 0.0033502819 | F4: 0.022547883 | G4: 0 | H4: 1710 | I4: 0.31578947 | J4: 0.028146386 | K4: 4.1292234 | L4: 0.40854289
A5: C1 CIS 52주신고가+정배열+K62상승 | B5: 879 | C5: 0.33902162 | D5: 0.024958339 | E5: 0.0034593329 | F5: 0.021499006 | G5: 0 | H5: 1394 | I5: 0.33715925 | J5: 0.037232768 | K5: 4.7103215 | L5: 0.40343159
A6: C2 CIS 52주신고가+거래량 | B6: 1049 | C6: 0.34413727 | D6: 0.0289317 | E6: 0.0044673084 | F6: 0.024464391 | G6: 0 | H6: 1612 | I6: 0.30521092 | J6: 0.027050302 | K6: 3.7588719 | L6: 0.43555054
A7: C2 CIS 52주신고가+거래량+K62상승 | B7: 774 | C7: 0.32945736 | D7: 0.024565007 | E7: 0.0042501997 | F7: 0.020314807 | G7: 0 | H7: 1319 | I7: 0.32145565 | J7: 0.034252659 | K7: 4.1293351 | L7: 0.44051601
A8: C3 CIS 55일신고가+정배열, 10일선청산 | B8: 3069 | C8: 0.31606386 | D8: 0.0029533338 | E8: 0.00045044126 | F8: 0.0025028925 | G8: 0 | H8: 4089 | I8: 0.33333333 | J8: 0.0071709696 | K8: 2.8091256 | L8: 0.21193071
A9: C3 CIS 55일신고가+정배열, 10일선청산+K62상승 | B9: 2017 | C9: 0.32672286 | D9: 0.0036854246 | E9: 0.00032496175 | F9: 0.0033604628 | G9: 0 | H9: 2855 | I9: 0.3614711 | J9: 0.014722976 | K9: 4.5345901 | L9: 0.21859606
A10: D1 다바스 (좁은박스20 상단돌파) | B10: 2041 | C10: 0.26065654 | D10: 0.010307718 | E10: 0.008814147 | F10: 0.0014935711 | G10: 0.4 | H10: 2257 | I10: 0.24988923 | J10: -0.00065083376 | K10: -0.18083603 | L10: 0.51884597
A11: D1 다바스 (좁은박스20 상단돌파)+K62상승 | B11: 1264 | C11: 0.29193038 | D11: 0.025138186 | E11: 0.008104528 | F11: 0.017033658 | G11: 0 | H11: 1390 | I11: 0.26906475 | J11: 0.0092455609 | K11: 1.729934 | L11: 0.52110023
A12: D2 다바스+거래량+248위 | B12: 972 | C12: 0.27777778 | D12: 0.025869905 | E12: 0.0040801589 | F12: 0.021789746 | G12: 0 | H12: 1060 | I12: 0.25566038 | J12: 0.0073139921 | K12: 1.0902655 | L12: 0.53641732
A13: D2 다바스+거래량+248위+K62상승 | B13: 714 | C13: 0.33053221 | D13: 0.043659513 | E13: 0.0016543115 | F13: 0.042005202 | G13: 0 | H13: 749 | I13: 0.27903872 | J13: 0.019397935 | K13: 2.0745485 | L13: 0.51948052
A14: D3 다바스 넓은박스(<20%)+거래량 | B14: 2982 | C14: 0.27364185 | D14: 0.013824195 | E14: 0.01730636 | F14: -0.0034821653 | G14: 0.8 | H14: 3891 | I14: 0.2690825 | J14: 0.014133451 | K14: 3.851007 | L14: 0.50109123
A15: D3 다바스 넓은박스(<20%)+거래량+K62상승 | B15: 1848 | C15: 0.29329004 | D15: 0.024101374 | E15: 0.015638901 | F15: 0.008462473 | G15: 0.025 | H15: 2471 | I15: 0.29138001 | J15: 0.028401164 | K15: 5.2288835 | L15: 0.50289419
... A91: W6 스프링55 + 거래량 돌파일<이탈일+K62상승 | B91: 1795 | C91: 0.36267409 | D91: -0.0087276155 | E91: 0.0025546878 | F91: -0.011282303 | G91: 1 | H91: 3951 | I91: 0.44343204 | J91: 0.0034552321 | K91: 2.365111 | L91: 0.18430212
